Workbook

Sheet Sheet1
R2: Data from PD report
B3: Settlement date | C3: 45803 | E3: Market shift | F3: 0
Y5: Average
B6: Liabilities | C6: Amount | D6: Maturities | E6: Years to maturity | F6: Yield rate | G6: PV | H6: Weights | I6: Mduration | J6: New value | K6: Time to maturity | P6: 17.00%2025A | Q6: 3 | R6: 45809 | S6: 6 | T6: 100.14298 | U6: 0.076833333 | V6: 100.14655 | W6: 0.074833333 | X6: 0.0035679975 | Y6: =AVERAGE(U6,W6) -> 0.075833333
B7: 1 | C7: 10091060 | D7: 46421 | E7: =(D7-$C$3)/364 -> 1.6978022 | F7: {=_xll.SRS1Splines.Functions25.Cubic_Spline(Sheet2!$N$2:$N$13,Sheet2!$O$2:$O$13,E7)+0.5%} -> 0.090427105 | G7: =C7*PRICE($C$3,D7,0,F7,1,2,1) -> 8689613 | H7: =G7/$G$17 -> 0.12963172 | I7: =MDURATION($C$3,D7,0,F7,2,1) -> 1.6174759 | J7: =C7*PRICE($C$3,D7,0,F7+$F$3,1,2,1) -> 8689613 | K7: =D7-$C$3 -> 618 | P7: 18.00%2025A | Q7: 3 | R7: 45839 | S7: 36 | T7: 100.95151 | U7: 0.077958333 | V7: 100.97464 | W7: 0.075791667 | X7: 0.023131159 | Y7: =AVERAGE(U7,W7) -> 0.076875
B8: 2 | C8: 10518678 | D8: 47053 | E8: =(D8-$C$3)/364 -> 3.4340659 | F8: {=_xll.SRS1Splines.Functions25.Cubic_Spline(Sheet2!$N$2:$N$13,Sheet2!$O$2:$O$13,E8)+0.5%} -> 0.10306454 | G8: =C8*PRICE($C$3,D8,0,F8,1,2,1) -> 7458665.8 | H8: =G8/$G$17 -> 0.11126844 | I8: =MDURATION($C$3,D8,0,F8,2,1) -> 3.2531242 | J8: =C8*PRICE($C$3,D8,0,F8+$F$3,1,2,1) -> 7458665.8 | K8: =D8-$C$3 -> 1250 | P8: 11.00%2025A | Q8: 10 | R8: 45870 | S8: 67 | T8: 100.52316 | U8: 0.0786 | V8: 100.56111 | W8: 0.0766 | X8: 0.037954423 | Y8: =AVERAGE(U8,W8) -> 0.0776
B9: 3 | C9: 11892833 | D9: 49825 | E9: =(D9-$C$3)/364 -> 11.049451 | F9: {=_xll.SRS1Splines.Functions25.Cubic_Spline(Sheet2!$N$2:$N$13,Sheet2!$O$2:$O$13,E9)+0.5%} -> 0.11912072 | G9: =C9*PRICE($C$3,D9,0,F9,1,2,1) -> 3326324.4 | H9: =G9/$G$17 -> 0.049622134 | I9: =MDURATION($C$3,D9,0,F9,2,1) -> 10.392093 | J9: =C9*PRICE($C$3,D9,0,F9+$F$3,1,2,1) -> 3326324.4 | K9: =D9-$C$3 -> 4022 | P9: 10.35%2025A | Q9: 8 | R9: 45945 | S9: 142 | T9: 100.86284 | U9: 0.07965 | V9: 100.93199 | W9: 0.07785 | X9: 0.069159435 | Y9: =AVERAGE(U9,W9) -> 0.07875
B10: 4 | C10: 12310437 | D10: 50249 | E10: =(D10-$C$3)/364 -> 12.214286 | F10: {=_xll.SRS1Splines.Functions25.Cubic_Spline(Sheet2!$N$2:$N$13,Sheet2!$O$2:$O$13,E10)+0.5%} -> 0.12036826 | G10: =C10*PRICE($C$3,D10,0,F10,1,2,1) -> 2966797.6 | H10: =G10/$G$17 -> 0.04425871 | I10: =MDURATION($C$3,D10,0,F10,2,1) -> 11.482942 | J10: =C10*PRICE($C$3,D10,0,F10+$F$3,1,2,1) -> 2966797.6 | K10: =D10-$C$3 -> 4446 | P10: 06.75%2026A | Q10: 5 | R10: 46037 | S10: 234 | T10: 99.144917 | U10: 0.0813 | V10: 99.242105 | W10: 0.0797 | X10: 0.097187463 | Y10: =AVERAGE(U10,W10) -> 0.0805
B11: 5 | C11: 12023565 | D11: 46448 | E11: =(D11-$C$3)/364 -> 1.771978 | F11: {=_xll.SRS1Splines.Functions25.Cubic_Spline(Sheet2!$N$2:$N$13,Sheet2!$O$2:$O$13,E11)+0.5%} -> 0.090909193 | G11: =C11*PRICE($C$3,D11,0,F11,1,2,1) -> 10273790 | H11: =G11/$G$17 -> 0.15326449 | I11: =MDURATION($C$3,D11,0,F11,2,1) -> 1.6921077 | J11: =C11*PRICE($C$3,D11,0,F11+$F$3,1,2,1) -> 10273790 | K11: =D11-$C$3 -> 645 | P11: 09.00%2026A | Q11: 13 | R11: 46054 | S11: 251 | T11: 100.52163 | U11: 0.081694444 | V11: 100.63156 | W11: 0.080027778 | X11: 0.10993489 | Y11: =AVERAGE(U11,W11) -> 0.080861111
B12: 6 | C12: 15669237 | D12: 49451 | E12: =(D12-$C$3)/364 -> 10.021978 | F12: {=_xll.SRS1Splines.Functions25.Cubic_Spline(Sheet2!$N$2:$N$13,Sheet2!$O$2:$O$13,E12)+0.5%} -> 0.11732467 | G12: =C12*PRICE($C$3,D12,0,F12,1,2,1) -> 5016915.7 | H12: =G12/$G$17 -> 0.074842388 | I12: =MDURATION($C$3,D12,0,F12,2,1) -> 9.4356152 | J12: =C12*PRICE($C$3,D12,0,F12+$F$3,1,2,1) -> 5016915.7 | K12: =D12-$C$3 -> 3648 | P12: 05.35%2026A | Q12: 15 | R12: 46082 | S12: 279 | T12: 97.87496 | U12: 0.0825 | V12: 97.996965 | W12: 0.0808 | X12: 0.12200496 | Y12: =AVERAGE(U12,W12) -> 0.08165
B13: 7 | C13: 16609183 | D13: 49924 | E13: =(D13-$C$3)/364 -> 11.321429 | F13: {=_xll.SRS1Splines.Functions25.Cubic_Spline(Sheet2!$N$2:$N$13,Sheet2!$O$2:$O$13,E13)+0.5%} -> 0.11948148 | G13: =C13*PRICE($C$3,D13,0,F13,1,2,1) -> 4485905.3 | H13: =G13/$G$17 -> 0.066920771 | I13: =MDURATION($C$3,D13,0,F13,2,1) -> 10.64401 | J13: =C13*PRICE($C$3,D13,0,F13+$F$3,1,2,1) -> 4485905.3 | K13: =D13-$C$3 -> 4121 | P13: 22.50%2026A | Q13: 4 | R13: 46157 | S13: 354 | T13: 112.92816 | U13: 0.083375 | V13: 113.08762 | W13: 0.081791667 | X13: 0.15945577 | Y13: =AVERAGE(U13,W13) -> 0.082583333
B14: 8 | C14: 14932483 | D14: 48860 | E14: =(D14-$C$3)/364 -> 8.3983516 | F14: {=_xll.SRS1Splines.Functions25.Cubic_Spline(Sheet2!$N$2:$N$13,Sheet2!$O$2:$O$13,E14)+0.5%} -> 0.11371934 | G14: =C14*PRICE($C$3,D14,0,F14,1,2,1) -> 5917484.6 | H14: =G14/$G$17 -> 0.088277081 | I14: =MDURATION($C$3,D14,0,F14,2,1) -> 7.9186033 | J14: =C14*PRICE($C$3,D14,0,F14+$F$3,1,2,1) -> 5917484.6 | K14: =D14-$C$3 -> 3057 | P14: 11.00%2026A | Q14: 11 | R14: 46174 | S14: 371 | T14: 102.51644 | U14: 0.083625 | V14: 102.66272 | W14: 0.082125 | X14: 0.14627464 | Y14: =AVERAGE(U14,W14) -> 0.082875
B15: 9 | C15: 16756607 | D15: 49955 | E15: =(D15-$C$3)/364 -> 11.406593 | F15: {=_xll.SRS1Splines.Functions25.Cubic_Spline(Sheet2!$N$2:$N$13,Sheet2!$O$2:$O$13,E15)+0.5%} -> 0.11958531 | G15: =C15*PRICE($C$3,D15,0,F15,1,2,1) -> 4475673.6 | H15: =G15/$G$17 -> 0.066768134 | I15: =MDURATION($C$3,D15,0,F15,2,1) -> 10.724853 | J15: =C15*PRICE($C$3,D15,0,F15+$F$3,1,2,1) -> 4475673.6 | K15: =D15-$C$3 -> 4152 | P15: 11.50%2026A | Q15: 10 | R15: 46235 | S15: 432 | T15: 103.3854 | U15: 0.084138889 | V15: 103.52444 | W15: 0.082916667 | X15: 0.13904185 | Y15: =AVERAGE(U15,W15) -> 0.083527778
B16: 10 | C16: 20534684 | D16: 47084 | E16: =(D16-$C$3)/364 -> 3.5192308 | F16: {=_xll.SRS1Splines.Functions25.Cubic_Spline(Sheet2!$N$2:$N$13,Sheet2!$O$2:$O$13,E16)+0.5%} -> 0.10346998 | G16: =C16*PRICE($C$3,D16,0,F16,1,2,1) -> 14421908 | H16: =G16/$G$17 -> 0.21514614 | I16: =MDURATION($C$3,D16,0,F16,2,1) -> 3.3304611 | J16: =C16*PRICE($C$3,D16,0,F16+$F$3,1,2,1) -> 14421908 | K16: =D16-$C$3 -> 1281 | P16: 11.25%2026A | Q16: 3 | R16: 46371 | S16: 568 | T16: 103.81057 | U16: 0.085722222 | V16: 103.9981 | W16: 0.084444444 | X16: 0.18752896 | Y16: =AVERAGE(U16,W16) -> 0.085083333
F17: Sum of PV | G17: =SUM(G7:G16) -> 67033079 | I17: =SUMPRODUCT(H7:H16,I7:I16) -> 5.4050191 | J17: =SUM(J7:J16) -> 67033079 | K17: =SUM(K7:K16) -> 27240 | P17: 11.40%2027A | Q17: 8 | R17: 46402 | S17: 599 | T17: 104.00223 | U17: 0.08709375 | V17: 104.17566 | W17: 0.08596875 | X17: 0.17342974 | Y17: =AVERAGE(U17,W17) -> 0.08653125
P18: 18.00%2027A | Q18: 5 | R18: 46508 | S18: 705 | T18: 115.69999 | U18: 0.089571429 | V18: 115.9335 | W18: 0.088357143 | X18: 0.23350839 | Y18: =AVERAGE(U18,W18) -> 0.088964286
P19: 11.75%2027A | Q19: 10 | R19: 46553 | S19: 750 | T19: 104.87715 | U19: 0.0908776 | V19: 105.18118 | W19: 0.0892776 | X19: 0.30402693 | Y19: =AVERAGE(U19,W19) -> 0.0900776
B20: Assets | P20: 07.80%2027A | Q20: 7 | R20: 46614 | S20: 811 | T20: 97.344625 | U20: 0.0913554 | V20: 97.655816 | W20: 0.0897554 | X20: 0.31119167 | Y20: =AVERAGE(U20,W20) -> 0.0905554
B21: Bonds and T-Bills | C21: Maturity | D21: Rate | E21: Yield | F21: Price | G21: Mduration | H21: Weights | I21: Value | J21: New price | K21: New value | P21: 20.00%2027A | Q21: 5 | R21: 46645 | S21: 842 | T21: 121.77188 | U21: 0.09264575 | V21: 122.07731 | W21: 0.09133325 | X21: 0.30543534 | Y21: =AVERAGE(U21,W21) -> 0.0919895
A22: Bonds | B22: 11.00%2029B | C22: 47467 | D22: =VALUE(LEFT(B22,5))/100 -> 0.11 | E22: =Y37 -> 0.101175 | F22: =PRICE($C$3,C22,D22,E22,100,2,1) -> 103.14503 | G22: =MDURATION($C$3,C22,D22,E22,2,1) -> 3.3794185 | H22: 0.002765398 | I22: =($G$17+769559.51)*H22 -> 187501.28 | J22: =PRICE($C$3,C22,D22,E22+$F$3,100,2,1) -> 103.14503 | K22: =I22/F22*J22 -> 187501.28 | P22: 10.30%2027A | Q22: 8 | R22: 46675 | S22: 872 | T22: 101.9696 | U22: 0.093509167 | V22: 102.28907 | W22: 0.092009167 | X22: 0.31946655 | Y22: =AVERAGE(U22,W22) -> 0.092759167
B23: 11.00%2030A | C23: 47618 | D23: =VALUE(LEFT(B23,5))/100 -> 0.11 | E23: =Y38 -> 0.1021625 | F23: =PRICE($C$3,C23,D23,E23,100,2,1) -> 102.98858 | G23: =MDURATION($C$3,C23,D23,E23,2,1) -> 3.7707698 | H23: 0 | I23: =($G$17+769559.51)*H23 -> 0 | J23: =PRICE($C$3,C23,D23,E23+$F$3,100,2,1) -> 102.98858 | K23: =I23/F23*J23 -> 0 | P23: 11.25%2027A | Q23: 10 | R23: 46736 | S23: 933 | T23: 104.15504 | U23: 0.093777714 | V23: 104.82737 | W23: 0.090849143 | X23: 0.67232552 | Y23: =AVERAGE(U23,W23) -> 0.092313429
B24: 11.25%2031A | C24: 47922 | D24: =VALUE(LEFT(B24,5))/100 -> 0.1125 | E24: =Y40 -> 0.10525 | F24: =PRICE($C$3,C24,D24,E24,100,2,1) -> 103.05613 | G24: =MDURATION($C$3,C24,D24,E24,2,1) -> 4.1327607 | H24: 0 | I24: =($G$17+769559.51)*H24 -> 0 | J24: =PRICE($C$3,C24,D24,E24+$F$3,100,2,1) -> 103.05613 | K24: =I24/F24*J24 -> 0 | P24: 10.75%2028B | Q24: 3 | R24: 46798 | S24: 995 | T24: 102.76927 | U24: 0.095580222 | V24: 103.00904 | W24: 0.094580222 | X24: 0.23976116 | Y24: =AVERAGE(U24,W24) -> 0.095080222
B25: 18.00%2031A | C25: 47983 | D25: =VALUE(LEFT(B25,5))/100 -> 0.18 | E25: =Y41 -> 0.10558333 | F25: =PRICE($C$3,C25,D25,E25,100,2,1) -> 132.33551 | G25: =MDURATION($C$3,C25,D25,E25,2,1) -> 3.9507278 | H25: 0.11907518 | I25: =($G$17+769559.51)*H25 -> 8073611.7 | J25: =PRICE($C$3,C25,D25,E25+$F$3,100,2,1) -> 132.33551 | K25: =I25/F25*J25 -> 8073611.7 | P25: 10.75%2028A | Q25: 10 | R25: 46827 | S25: 1024 | T25: 102.70584 | U25: 0.096138875 | V25: 103.16703 | W25: 0.094263875 | X25: 0.46118705 | Y25: =AVERAGE(U25,W25) -> 0.095201375
B26: 12.00%2031A | C26: 48183 | D26: =VALUE(LEFT(B26,5))/100 -> 0.12 | E26: =Y42 -> 0.10607143 | F26: =PRICE($C$3,C26,D26,E26,100,2,1) -> 106.43045 | G26: =MDURATION($C$3,C26,D26,E26,2,1) -> 4.2885168 | H26: 0.035730634 | I26: =($G$17+769559.51)*H26 -> 2422631.3 | J26: =PRICE($C$3,C26,D26,E26+$F$3,100,2,1) -> 106.43045 | K26: =I26/F26*J26 -> 2422631.3 | P26: 09.00%2028B | Q26: 15 | R26: 46874 | S26: 1071 | T26: 98.314919 | U26: 0.0966875 | V26: 98.780567 | W26: 0.0948125 | X26: 0.46564827 | Y26: =AVERAGE(U26,W26) -> 0.09575
B27: 08.00%2032A | C27: 48214 | D27: =VALUE(LEFT(B27,5))/100 -> 0.08 | E27: =Y43 -> 0.1078 | F27: =PRICE($C$3,C27,D27,E27,100,2,1) -> 87.091994 | G27: =MDURATION($C$3,C27,D27,E27,2,1) -> 4.7071893 | H27: 0.03872798 | I27: =($G$17+769559.51)*H27 -> 2625859.2 | J27: =PRICE($C$3,C27,D27,E27+$F$3,100,2,1) -> 87.091994 | K27: =I27/F27*J27 -> 2625859.2 | P27: 09.00%2028A | Q27: 15 | R27: 46935 | S27: 1132 | T27: 98.137244 | U27: 0.0970375 | V27: 98.618601 | W27: 0.0951875 | X27: 0.48135687 | Y27: =AVERAGE(U27,W27) -> 0.0961125
B28: 18.00%2032A | C28: 48396 | D28: =VALUE(LEFT(B28,5))/100 -> 0.18 | E28: =Y44 -> 0.10754167 | F28: =PRICE($C$3,C28,D28,E28,100,2,1) -> 135.31041 | G28: =MDURATION($C$3,C28,D28,E28,2,1) -> 4.2175976 | H28: 0.035222909 | I28: =($G$17+769559.51)*H28 -> 2388206.2 | J28: =PRICE($C$3,C28,D28,E28+$F$3,100,2,1) -> 135.31041 | K28: =I28/F28*J28 -> 2388206.2 | P28: 11.50%2028A | Q28: 13 | R28: 46997 | S28: 1194 | T28: 104.74501 | U28: 0.0975625 | V28: 105.25884 | W28: 0.09575 | X28: 0.51382514 | Y28: =AVERAGE(U28,W28) -> 0.09665625
B29: 09.00%2032A | C29: 48488 | D29: =VALUE(LEFT(B29,5))/100 -> 0.09 | E29: =Y45 -> 0.10783333 | F29: =PRICE($C$3,C29,D29,E29,100,2,1) -> 91.079958 | G29: =MDURATION($C$3,C29,D29,E29,2,1) -> 5.0829603 | H29: 0.041418189 | I29: =($G$17+769559.51)*H29 -> 2808262.5 | J29: =PRICE($C$3,C29,D29,E29+$F$3,100,2,1) -> 91.079958 | K29: =I29/F29*J29 -> 2808262.5 | P29: 11.00%2028A | Q29: 4 | R29: 47041 | S29: 1238 | T29: 103.29513 | U29: 0.09825 | V29: 103.6384 | W29: 0.0970625 | X29: 0.3432738 | Y29: =AVERAGE(U29,W29) -> 0.09765625
B30: 11.50%2032A | C30: 48563 | D30: =VALUE(LEFT(B30,5))/100 -> 0.115 | E30: =Y46 -> 0.107875 | F30: =PRICE($C$3,C30,D30,E30,100,2,1) -> 103.60369 | G30: =MDURATION($C$3,C30,D30,E30,2,1) -> 4.7841447 | H30: 0.03927892 | I30: =($G$17+769559.51)*H30 -> 2663214.4 | J30: =PRICE($C$3,C30,D30,E30+$F$3,100,2,1) -> 103.60369 | K30: =I30/F30*J30 -> 2663214.4 | P30: 11.50%2028B | Q30: 5 | R30: 47102 | S30: 1299 | T30: 104.79834 | U30: 0.098625 | V30: 105.17775 | W30: 0.097375 | X30: 0.37941279 | Y30: =AVERAGE(U30,W30) -> 0.098
B31: 11.20%2033A | C31: 48594 | D31: =VALUE(LEFT(B31,5))/100 -> 0.112 | E31: =Y47 -> 0.109 | F31: =PRICE($C$3,C31,D31,E31,100,2,1) -> 101.4989 | G31: =MDURATION($C$3,C31,D31,E31,2,1) -> 4.8791483 | H31: 0.039959067 | I31: =($G$17+769559.51)*H31 -> 2709330.2 | J31: =PRICE($C$3,C31,D31,E31+$F$3,100,2,1) -> 101.4989 | K31: =I31/F31*J31 -> 2709330.2 | P31: 13.00%2029A | Q31: 15 | R31: 47119 | S31: 1316 | T31: 108.76625 | U31: 0.1003 | V31: 109.14214 | W31: 0.0991 | X31: 0.3758974 | Y31: =AVERAGE(U31,W31) -> 0.0997
B32: 09.00%2033A | C32: 48731 | D32: =VALUE(LEFT(B32,5))/100 -> 0.09 | E32: =Y48 -> 0.10915 | F32: =PRICE($C$3,C32,D32,E32,100,2,1) -> 89.935682 | G32: =MDURATION($C$3,C32,D32,E32,2,1) -> 5.1980117 | H32: 0.042241865 | I32: =($G$17+769559.51)*H32 -> 2864109.9 | J32: =PRICE($C$3,C32,D32,E32+$F$3,100,2,1) -> 89.935682 | K32: =I32/F32*J32 -> 2864109.9 | P32: 13.00%2029B | Q32: 15 | R32: 47239 | S32: 1436 | T32: 109.06951 | U32: 0.1014 | V32: 109.47371 | W32: 0.1002 | X32: 0.40419687 | Y32: =AVERAGE(U32,W32) -> 0.1008
B33: 13.25%2033A | C33: 48761 | D33: =VALUE(LEFT(B33,5))/100 -> 0.1325 | E33: =Y49 -> 0.1094125 | F33: =PRICE($C$3,C33,D33,E33,100,2,1) -> 112.16867 | G33: =MDURATION($C$3,C33,D33,E33,2,1) -> 4.8660246 | H33: 0.03986511 | I33: =($G$17+769559.51)*H33 -> 2702959.6 | J33: =PRICE($C$3,C33,D33,E33+$F$3,100,2,1) -> 112.16867 | K33: =I33/F33*J33 -> 2702959.6 | P33: 11.75%2029A | Q33: 5 | R33: 47284 | S33: 1481 | T33: 105.47911 | U33: 0.10066667 | V33: 105.83632 | W33: 0.099611111 | X33: 0.35721771 | Y33: =AVERAGE(U33,W33) -> 0.10013889
B34: 09.00%2033B | C34: 48884 | D34: =VALUE(LEFT(B34,5))/100 -> 0.09 | E34: =Y50 -> 0.10892188 | F34: =PRICE($C$3,C34,D34,E34,100,2,1) -> 89.717406 | G34: =MDURATION($C$3,C34,D34,E34,2,1) -> 5.5944278 | H34: 0.045079873 | I34: =($G$17+769559.51)*H34 -> 3056534.3 | J34: =PRICE($C$3,C34,D34,E34+$F$3,100,2,1) -> 89.717406 | K34: =I34/F34*J34 -> 3056534.3 | P34: 20.00%2029A | Q34: 7 | R34: 47314 | S34: 1511 | T34: 132.46384 | U34: 0.101772 | V34: 132.9453 | W34: 0.100568 | X34: 0.48145706 | Y34: =AVERAGE(U34,W34) -> 0.10117
B35: 13.25%2034A | C35: 48945 | D35: =VALUE(LEFT(B35,5))/100 -> 0.1325 | E35: =Y51 -> 0.1143875 | F35: =PRICE($C$3,C35,D35,E35,100,2,1) -> 109.72112 | G35: =MDURATION($C$3,C35,D35,E35,2,1) -> 4.993077 | H35: 0.040774705 | I35: =($G$17+769559.51)*H35 -> 2764632.6 | J35: =PRICE($C$3,C35,D35,E35+$F$3,100,2,1) -> 109.72112 | K35: =I35/F35*J35 -> 2764632.6 | P35: 11.00%2029A | Q35: 7 | R35: 47376 | S35: 1573 | T35: 102.99831 | U35: 0.101142 | V35: 103.3564 | W35: 0.100118 | X35: 0.35809082 | Y35: =AVERAGE(U35,W35) -> 0.10063
... B43: 12.50%2045A | C43: 53022 | D43: =VALUE(LEFT(B43,5))/100 -> 0.125 | E43: =Y59 -> 0.11403125 | F43: =PRICE($C$3,C43,D43,E43,100,2,1) -> 108.50165 | G43: =MDURATION($C$3,C43,D43,E43,2,1) -> 7.4869768 | H43: 0.058628957 | I43: =($G$17+769559.51)*H43 -> 3975198 | J43: =PRICE($C$3,C43,D43,E43+$F$3,100,2,1) -> 108.50165 | K43: =I43/F43*J43 -> 3975198 | P43: 08.00%2032A | Q43: 20 | R43: 48214 | S43: 2411 | T43: 86.742223 | U43: 0.108625 | V43: 87.443546 | W43: 0.106975 | X43: 0.70132319 | Y43: =AVERAGE(U43,W43) -> 0.1078
A44: T-Bills | B44: 3Months | C44: 45895 | D44: 0 | E44: =V67 -> 0.075138889 | F44: =PRICE($C$3,C44,D44,E44,100,2,1) -> 98.126176 | G44: =MDURATION($C$3,C44,D44,E44,2,1) -> 0.24494134 | H44: 0.017937698 | I44: =($G$17+769559.51)*H44 -> 1216223.3 | J44: =PRICE($C$3,C44,D44,E44+$F$3,100,2,1) -> 98.126176 | K44: =I44/F44*J44 -> 1216223.3 | P44: 18.00%2032A | Q44: 10 | R44: 48396 | S44: 2593 | T44: 134.83569 | U44: 0.10833333 | V44: 135.78742 | W44: 0.10675 | X44: 0.95173563 | Y44: =AVERAGE(U44,W44) -> 0.10754167
B45: 6 Months | C45: 45987 | D45: 0 | E45: =V68 -> 0.077277778 | F45: =PRICE($C$3,C45,D45,E45,100,2,1) -> 96.279853 | G45: =MDURATION($C$3,C45,D45,E45,2,1) -> 0.48139927 | H45: 0.016793134 | I45: =($G$17+769559.51)*H45 -> 1138618.8 | J45: =PRICE($C$3,C45,D45,E45+$F$3,100,2,1) -> 96.279853 | K45: =I45/F45*J45 -> 1138618.8 | P45: 09.00%2032A | Q45: 20 | R45: 48488 | S45: 2685 | T45: 90.708988 | U45: 0.108625 | V45: 91.45289 | W45: 0.10704167 | X45: 0.74390186 | Y45: =AVERAGE(U45,W45) -> 0.10783333
B46: 1Year | C46: 46168 | D46: 0 | E46: =V69 -> 0.08104 | F46: =PRICE($C$3,C46,D46,E46,100,2,1) -> 92.363235 | G46: =MDURATION($C$3,C46,D46,E46,2,1) -> 0.96105793 | H46: 0.014471367 | I46: =($G$17+769559.51)*H46 -> 981196.84 | J46: =PRICE($C$3,C46,D46,E46+$F$3,100,2,1) -> 92.363235 | K46: =I46/F46*J46 -> 981196.84 | P46: 11.50%2032A | Q46: 8 | R46: 48563 | S46: 2760 | T46: 103.193 | U46: 0.10866667 | V46: 104.01656 | W46: 0.10708333 | X46: 0.82356079 | Y46: =AVERAGE(U46,W46) -> 0.107875
G47: =SUMPRODUCT(G22:G46,H22:H46) -> 5.41 | H47: =SUM(H22:H46) -> 1 | I47: =$G$17*H47 -> 67033079 | K47: =SUM(K22:K46) -> 67802638 | P47: 11.20%2033A | Q47: 15 | R47: 48594 | S47: 2791 | T47: 101.0624 | U47: 0.10985 | V47: 101.93791 | W47: 0.10815 | X47: 0.87551146 | Y47: =AVERAGE(U47,W47) -> 0.109
P48: 09.00%2033A | Q48: 20 | R48: 48731 | S48: 2928 | T48: 89.520352 | U48: 0.11 | V48: 90.353539 | W48: 0.1083 | X48: 0.83318705 | Y48: =AVERAGE(U48,W48) -> 0.10915
P49: 13.25%2033A | Q49: 20 | R49: 48761 | S49: 2958 | T49: 111.6771 | U49: 0.110275 | V49: 112.66319 | W49: 0.10855 | X49: 0.98608755 | Y49: =AVERAGE(U49,W49) -> 0.1094125
...

Sheet Sheet2
A1: Weighted Average Yield Rates ( % Per Annum) | C1: Last Primary Auctions | D1: Last Traded Secondary Market Rates ( Reported by PDs.) | E1: Two Way Quotes for | F1: 45803 | N1: Years to maturity | O1: Yield rate
E2: Bid | F2: Offer | G2: Average | M2: < 91 Days | N2: =3/12 -> 0.25 | O2: =G3 -> 0.075138889
A3: Treasury Bills | B3: < 91 Days | C3: 0.0765 | D3: 0.074723312 | E3: 0.076111111 | F3: 0.074166667 | G3: =AVERAGE(E3,F3) -> 0.075138889 | M3: < 182 Days | N3: =6/12 -> 0.5 | O3: =G4 -> 0.077277778
B4: < 182 Days | C4: 0.0797 | D4: 0.078051253 | E4: 0.078166667 | F4: 0.076388889 | G4: =AVERAGE(E4,F4) -> 0.077277778 | M4: < 364 Days | N4: 1 | O4: =G5 -> 0.08104
B5: < 364 Days | C5: 0.0829 | D5: 0.081587809 | E5: 0.08173 | F5: 0.08035 | G5: =AVERAGE(E5,F5) -> 0.08104 | M5: < 2 Year | N5: 2 | O5: =G6 -> 0.087494665
A6: Treasury Bonds | B6: < 2 Year | C6: 0.1383 | D6: 0.082909848 | E6: 0.088191421 | F6: 0.086797909 | G6: =AVERAGE(E6,F6) -> 0.087494665 | M6: < 3 Year | N6: 3 | O6: =G7 -> 0.095473328
B7: < 3 Year | C7: 0.1179 | D7: 0.094498298 | E7: 0.096325114 | F7: 0.094621543 | G7: =AVERAGE(E7,F7) -> 0.095473328 | M7: < 4 Year | N7: 4 | O7: =G8 -> 0.10017698
B8: < 4 Year | C8: 0.1022 | D8: 0.103 | E8: 0.10075033 | F8: 0.099603635 | G8: =AVERAGE(E8,F8) -> 0.10017698 | M8: < 5 Year | N8: 5 | O8: =G9 -> 0.1020994
B9: < 5 Year | C9: 0.1064 | D9: 0.09925 | E9: 0.10269988 | F9: 0.10149893 | G9: =AVERAGE(E9,F9) -> 0.1020994 | M9: < 6 Year | N9: 6 | O9: =G10 -> 0.10541667
B10: < 6 Year | C10: 0.1096 | D10: 0.10737981 | E10: 0.10609375 | F10: 0.10473958 | G10: =AVERAGE(E10,F10) -> 0.10541667 | M10: < 8 Year | N10: 8 | O10: =G11 -> 0.10808549
B11: < 8 Year | C11: 0.1097 | D11: - | E11: 0.10889063 | F11: 0.10728036 | G11: =AVERAGE(E11,F11) -> 0.10808549 | M11: <10 Year | N11: 10 | O11: =G12 -> 0.11227824
B12: <10 Year | C12: 0.1122 | D12: 0.10955 | E12: 0.11352522 | F12: 0.11103125 | G12: =AVERAGE(E12,F12) -> 0.11227824 | M12: < 15 Year | N12: 15 | O12: =G13 -> 0.1159125
B13: < 15 Year | C13: 0.1314 | D13: - | E13: 0.117975 | F13: 0.11385 | G13: =AVERAGE(E13,F13) -> 0.1159125 | M13: < 20 Year | N13: 20 | O13: =G14 -> 0.1130375
B14: < 20 Year | C14: 0.1068 | D14: - | E14: 0.114475 | F14: 0.1116 | G14: =AVERAGE(E14,F14) -> 0.1130375
B15: < 30 Year | C15: 0.1215 | D15: - | E15: - | F15: -
